Workbook

Sheet Dash_Board
A1: PepsiCo Social Media Performance Dashboard
A5: Top Performer | E5: Most Successful Campaign
A7: Facebook | C7: Maximum reach and brand awareness, Facebook is the top performer | E7: The most successful campaign is FestiveRadiance, which achieved the highest number of Impressions, Likes, and Comments, along with one of the lowest Cost per Engagement. This combination of high visibility, strong audience interaction, and cost-efficiency clearly positions FestiveRadiance as the top performing campaign ........................................ Note: The highest Impression, Like and Engagement rate were observed during periods with no active campaign

Sheet Posts
A1: Post ID | B1: Platform | C1: Date | D1: Content Type | E1: Post Text | F1: Likes | G1: Shares | H1: Comments | I1: Impressions | J1: Reach | K1: Clicks | L1: Hashtags Used | M1: Campaign_Name
A2: P001 | B2: Twitter | C2: 2024-12-23 | D2: Reel | E2: Check out our latest reel on twitter! | F2: 1461 | G2: 184 | H2: 344 | I2: 21915 | J2: 21675 | K2: 15 | L2: #LiveForNow,#AnytimeIsPepsiTime | M2: SummerSplash
A3: P002 | B3: Twitter | C3: 2025-04-03 | D3: Text | E3: Check out our latest text on twitter! | F3: 4054 | G3: 389 | H3: 493 | I3: 64864 | J3: 64383 | K3: 117 | L3: #PepsiCoRefresh,#BetterWithPepsi | M3: FestiveRadiance
A4: P003 | B4: YouTube | C4: 2025-05-12 | D4: Reel | E4: Check out our latest reel on youtube! | F4: 2795 | G4: 105 | H4: 49 | I4: 53105 | J4: 52307 | K4: 204 | L4: #PepsiCoRefresh | M4: NewYearRefresh
A5: P004 | B5: Instagram | C5: 2024-08-12 | D5: Story | E5: Check out our latest story on instagram! | F5: 2404 | G5: 363 | H5: 138 | I5: 19232 | J5: 18636 | K5: 128 | L5: #ThirstyForMore | M5: DailyWellness
A6: P005 | B6: YouTube | C6: 2024-06-26 | D6: Reel | E6: Check out our latest reel on youtube! | F6: 3557 | G6: 687 | H6: 424 | I6: 71140 | J6: 70701 | K6: 224 | L6: #ThirstyForMore,#PepsiCoRefresh | M6: SummerSplash
A7: P006 | B7: Facebook | C7: 2024-10-31 | D7: Carousel | E7: Check out our latest carousel on facebook! | F7: 2945 | G7: 930 | H7: 355 | I7: 23560 | J7: 23275 | K7: 256 | L7: #PepsiCoRefresh | M7: FestiveRadiance
A8: P007 | B8: Twitter | C8: 2024-06-24 | D8: Carousel | E8: Check out our latest carousel on twitter! | F8: 3860 | G8: 201 | H8: 279 | I8: 61760 | J8: 61660 | K8: 235 | L8: #PepsiCoRefresh | M8: FestiveRadiance
A9: P008 | B9: YouTube | C9: 2024-07-13 | D9: Image | E9: Check out our latest image on youtube! | F9: 3929 | G9: 262 | H9: 278 | I9: 43219 | J9: 42841 | K9: 39 | L9: #ThirstyForMore | M9: DailyWellness
A10: P009 | B10: Facebook | C10: 2024-08-30 | D10: Text | E10: Check out our latest text on facebook! | F10: 3784 | G10: 808 | H10: 404 | I10: 56760 | J10: 56343 | K10: 131 | L10: #PepsiCoRefresh | M10: FestiveRadiance
A11: P010 | B11: Facebook | C11: 2025-03-11 | D11: Image | E11: Check out our latest image on facebook! | F11: 4241 | G11: 902 | H11: 47 | I11: 72097 | J11: 71598 | K11: 167 | L11: #PepsiCoRefresh | M11: FestiveRadiance
A12: P011 | B12: Instagram | C12: 2025-02-02 | D12: Story | E12: Check out our latest story on instagram! | F12: 1792 | G12: 614 | H12: 497 | I12: 25088 | J12: 24675 | K12: 65 | L12: #LiveForNow | M12: DailyWellness
A13: P012 | B13: Facebook | C13: 2024-07-21 | D13: Reel | E13: Check out our latest reel on facebook! | F13: 1946 | G13: 686 | H13: 377 | I13: 23352 | J13: 22982 | K13: 213 | L13: #LiveForNow | M13: NewYearRefresh
A14: P013 | B14: YouTube | C14: 2024-11-18 | D14: Carousel | E14: Check out our latest carousel on youtube! | F14: 1171 | G14: 286 | H14: 231 | I14: 22249 | J14: 21282 | K14: 114 | L14: #ThirstyForMore | M14: SummerSplash
A15: P014 | B15: Facebook | C15: 2025-02-16 | D15: Story | E15: Check out our latest story on facebook! | F15: 4242 | G15: 555 | H15: 131 | I15: 33936 | J15: 33802 | K15: 265 | L15: #LiveForNow
A16: P015 | B16: Facebook | C16: 2024-10-24 | D16: Video | E16: Check out our latest video on facebook! | F16: 3888 | G16: 604 | H16: 128 | I16: 77760 | J16: 77167 | K16: 20 | L16: #LiveForNow | M16: SummerSplash
A17: P016 | B17: Facebook | C17: 2024-08-26 | D17: Text | E17: Check out our latest text on facebook! | F17: 3452 | G17: 377 | H17: 360 | I17: 55232 | J17: 55075 | K17: 87 | L17: #LiveForNow | M17: NewYearRefresh
A18: P017 | B18: Facebook | C18: 2025-05-05 | D18: Text | E18: Check out our latest text on facebook! | F18: 4441 | G18: 511 | H18: 70 | I18: 53292 | J18: 53082 | K18: 159 | L18: #ThirstyForMore | M18: DailyWellness
A19: P018 | B19: Instagram | C19: 2024-08-19 | D19: Reel | E19: Check out our latest reel on instagram! | F19: 3000 | G19: 382 | H19: 325 | I19: 36000 | J19: 35819 | K19: 19 | L19: #LiveForNow | M19: SummerSplash
A20: P019 | B20: Instagram | C20: 2024-06-23 | D20: Video | E20: Check out our latest video on instagram! | F20: 1071 | G20: 519 | H20: 22 | I20: 16065 | J20: 15865 | K20: 103 | L20: #PepsiCoRefresh | M20: DailyWellness
A21: P020 | B21: Instagram | C21: 2024-09-09 | D21: Carousel | E21: Check out our latest carousel on instagram! | F21: 4054 | G21: 488 | H21: 373 | I21: 77026 | J21: 76881 | K21: 25 | L21: #PepsiCoRefresh | M21: SummerSplash
A22: P021 | B22: Instagram | C22: 2025-01-04 | D22: Reel | E22: Check out our latest reel on instagram! | F22: 4838 | G22: 640 | H22: 128 | I22: 72570 | J22: 72396 | K22: 83 | L22: #LiveForNow | M22: DailyWellness
A23: P022 | B23: Facebook | C23: 2025-02-27 | D23: Text | E23: Check out our latest text on facebook! | F23: 1570 | G23: 187 | H23: 260 | I23: 25120 | J23: 24613 | K23: 133 | L23: #PepsiCoRefresh | M23: DailyWellness
A24: P023 | B24: Facebook | C24: 2024-11-06 | D24: Video | E24: Check out our latest video on facebook! | F24: 1606 | G24: 547 | H24: 316 | I24: 32120 | J24: 31736 | K24: 225 | L24: #PepsiCoRefresh,#AnytimeIsPepsiTime | M24: FestiveRadiance
A25: P024 | B25: Facebook | C25: 2025-01-23 | D25: Video | E25: Check out our latest video on facebook! | F25: 3961 | G25: 761 | H25: 131 | I25: 67337 | J25: 66615 | K25: 161 | L25: #LiveForNow | M25: NewYearRefresh
A26: P025 | B26: Twitter | C26: 2025-04-10 | D26: Carousel | E26: Check out our latest carousel on twitter! | F26: 3128 | G26: 211 | H26: 197 | I26: 59432 | J26: 59182 | K26: 238 | L26: #ThirstyForMore
A27: P026 | B27: YouTube | C27: 2025-04-05 | D27: Reel | E27: Check out our latest reel on youtube! | F27: 3009 | G27: 413 | H27: 358 | I27: 42126 | J27: 41309 | K27: 211 | L27: #LiveForNow | M27: FestiveRadiance
A28: P027 | B28: YouTube | C28: 2024-09-17 | D28: Text | E28: Check out our latest text on youtube! | F28: 2076 | G28: 195 | H28: 104 | I28: 33216 | J28: 32244 | K28: 51 | L28: #LiveForNow | M28: DailyWellness
A29: P028 | B29: Instagram | C29: 2025-03-04 | D29: Video | E29: Check out our latest video on instagram! | F29: 432 | G29: 624 | H29: 123 | I29: 6912 | J29: 6259 | K29: 79 | L29: #LiveForNow | M29: DailyWellness
A30: P029 | B30: Instagram | C30: 2025-01-31 | D30: Carousel | E30: Check out our latest carousel on instagram! | F30: 2566 | G30: 118 | H30: 37 | I30: 12830 | J30: 12264 | K30: 221 | L30: #LiveForNow | M30: NewYearRefresh
A31: P030 | B31: Instagram | C31: 2025-02-25 | D31: Video | E31: Check out our latest video on instagram! | F31: 3095 | G31: 39 | H31: 78 | I31: 55710 | J31: 54808 | K31: 93 | L31: #ThirstyForMore
A32: P031 | B32: Instagram | C32: 2024-12-16 | D32: Text | E32: Check out our latest text on instagram! | F32: 438 | G32: 153 | H32: 275 | I32: 3066 | J32: 2701 | K32: 282 | L32: #PepsiCoRefresh | M32: FestiveRadiance
A33: P032 | B33: Twitter | C33: 2024-07-31 | D33: Carousel | E33: Check out our latest carousel on twitter! | F33: 2278 | G33: 10 | H33: 321 | I33: 13668 | J33: 12676 | K33: 275 | L33: #ThirstyForMore | M33: SummerSplash
A34: P033 | B34: Facebook | C34: 2024-08-21 | D34: Image | E34: Check out our latest image on facebook! | F34: 1407 | G34: 400 | H34: 351 | I34: 16884 | J34: 15954 | K34: 113 | L34: #PepsiCoRefresh | M34: SummerSplash
A35: P034 | B35: Facebook | C35: 2025-03-26 | D35: Text | E35: Check out our latest text on facebook! | F35: 1652 | G35: 89 | H35: 357 | I35: 29736 | J35: 28771 | K35: 215 | L35: #PepsiCoRefresh | M35: NewYearRefresh
A36: P035 | B36: Instagram | C36: 2024-11-30 | D36: Video | E36: Check out our latest video on instagram! | F36: 3775 | G36: 16 | H36: 239 | I36: 33975 | J36: 33310 | K36: 271 | L36: #LiveForNow | M36: FestiveRadiance
A37: P036 | B37: Instagram | C37: 2025-04-19 | D37: Story | E37: Check out our latest story on instagram! | F37: 4518 | G37: 285 | H37: 383 | I37: 67770 | J37: 67621 | K37: 31 | L37: #ThirstyForMore | M37: FestiveRadiance
A38: P037 | B38: Facebook | C38: 2025-01-06 | D38: Carousel | E38: Check out our latest carousel on facebook! | F38: 3024 | G38: 925 | H38: 350 | I38: 24192 | J38: 23518 | K38: 36 | L38: #ThirstyForMore | M38: FestiveRadiance
A39: P038 | B39: YouTube | C39: 2025-02-17 | D39: Reel | E39: Check out our latest reel on youtube! | F39: 3138 | G39: 123 | H39: 291 | I39: 28242 | J39: 27550 | K39: 87 | L39: #PepsiCoRefresh | M39: DailyWellness
A40: P039 | B40: Facebook | C40: 2024-11-25 | D40: Image | E40: Check out our latest image on facebook! | F40: 3564 | G40: 629 | H40: 177 | I40: 60588 | J40: 59627 | K40: 92 | L40: #PepsiCoRefresh
...

Sheet Cleaned_Data
A1: Post ID | B1: Platform | C1: Date | D1: Content Type | E1: Post Text | F1: Likes | G1: Shares | H1: Comments | I1: Impressions | J1: Reach | K1: Clicks | L1: Hashtags Used | M1: Campaign_Name | N1: Total Engagement | O1: Engagement Rate | P1: Campaign_Name2 | Q1: Start Date | R1: End Date | S1: Budget | T1: Per-Post Budget
A2: P001 | B2: Twitter | C2: 45649 | D2: Reel | E2: Check out our latest reel on twitter! | F2: 1461 | G2: 184 | H2: 344 | I2: 21915 | J2: 21675 | K2: 15 | L2: #LiveForNow,#AnytimeIsPepsiTime | M2: SummerSplash | N2: =SUM(F2,G2,H2) -> 1989 | O2: =IFERROR((Table1[[#This Row],[Likes]]+Table1[[#This Row],[Shares]]+Table1[[#This Row],[Comments]])/Table1[[#This Row],[Impressions]], 0) -> 0.090759754 | P2: {=IFERROR(INDEX('Campaign Metadata (2)'!$A$2:$A$10, MATCH(1, (C2>='Campaign Metadata (2)'!$B$2:$B$10) * (C2<='Campaign Metadata (2)'!$C$2:$C$10), 0)), "No Campaign")} -> No Campaign | Q2: =VLOOKUP(Table1[[#This Row],[Campaign_Name2]],Table3[#All],2,) -> #N/A | R2: =VLOOKUP(Table1[[#This Row],[Campaign_Name2]],Table3[#All],3,FALSE) -> #N/A | S2: =VLOOKUP(Table1[[#This Row],[Campaign_Name2]],Table3[],5,FALSE) -> #N/A | T2: =IF(Table1[[#This Row],[Campaign_Name2]]="No Campaign", 0, Table1[[#This Row],[Budget]]/COUNTIF(Table1[Campaign_Name2],Table1[[#This Row],[Campaign_Name2]])) -> 0
A3: P002 | B3: Twitter | C3: 45750 | D3: Text | E3: Check out our latest text on twitter! | F3: 4054 | G3: 389 | H3: 493 | I3: 64864 | J3: 64383 | K3: 117 | L3: #PepsiCoRefresh,#BetterWithPepsi | M3: FestiveRadiance | N3: =SUM(F3,G3,H3) -> 4936 | O3: =IFERROR((Table1[[#This Row],[Likes]]+Table1[[#This Row],[Shares]]+Table1[[#This Row],[Comments]])/Table1[[#This Row],[Impressions]], 0) -> 0.076097681 | P3: {=IFERROR(INDEX('Campaign Metadata (2)'!$A$2:$A$10, MATCH(1, (C3>='Campaign Metadata (2)'!$B$2:$B$10) * (C3<='Campaign Metadata (2)'!$C$2:$C$10), 0)), "No Campaign")} -> No Campaign | Q3: =VLOOKUP(Table1[[#This Row],[Campaign_Name2]],Table3[#All],2,) -> #N/A | R3: =VLOOKUP(Table1[[#This Row],[Campaign_Name2]],Table3[#All],3,FALSE) -> #N/A | S3: =VLOOKUP(Table1[[#This Row],[Campaign_Name2]],Table3[],5,FALSE) -> #N/A | T3: =IF(Table1[[#This Row],[Campaign_Name2]]="No Campaign", 0, Table1[[#This Row],[Budget]]/COUNTIF(Table1[Campaign_Name2],Table1[[#This Row],[Campaign_Name2]])) -> 0
A4: P003 | B4: YouTube | C4: 45789 | D4: Reel | E4: Check out our latest reel on youtube! | F4: 2795 | G4: 105 | H4: 49 | I4: 53105 | J4: 52307 | K4: 204 | L4: #PepsiCoRefresh | M4: NewYearRefresh | N4: =SUM(F4,G4,H4) -> 2949 | O4: =IFERROR((Table1[[#This Row],[Likes]]+Table1[[#This Row],[Shares]]+Table1[[#This Row],[Comments]])/Table1[[#This Row],[Impressions]], 0) -> 0.055531494 | P4: {=IFERROR(INDEX('Campaign Metadata (2)'!$A$2:$A$10, MATCH(1, (C4>='Campaign Metadata (2)'!$B$2:$B$10) * (C4<='Campaign Metadata (2)'!$C$2:$C$10), 0)), "No Campaign")} -> No Campaign | Q4: =VLOOKUP(Table1[[#This Row],[Campaign_Name2]],Table3[#All],2,) -> #N/A | R4: =VLOOKUP(Table1[[#This Row],[Campaign_Name2]],Table3[#All],3,FALSE) -> #N/A | S4: =VLOOKUP(Table1[[#This Row],[Campaign_Name2]],Table3[],5,FALSE) -> #N/A | T4: =IF(Table1[[#This Row],[Campaign_Name2]]="No Campaign", 0, Table1[[#This Row],[Budget]]/COUNTIF(Table1[Campaign_Name2],Table1[[#This Row],[Campaign_Name2]])) -> 0
A5: P004 | B5: Instagram | C5: 45516 | D5: Story | E5: Check out our latest story on instagram! | F5: 2404 | G5: 363 | H5: 138 | I5: 19232 | J5: 18636 | K5: 128 | L5: #ThirstyForMore | M5: DailyWellness | N5: =SUM(F5,G5,H5) -> 2905 | O5: =IFERROR((Table1[[#This Row],[Likes]]+Table1[[#This Row],[Shares]]+Table1[[#This Row],[Comments]])/Table1[[#This Row],[Impressions]], 0) -> 0.15105033 | P5: {=IFERROR(INDEX('Campaign Metadata (2)'!$A$2:$A$10, MATCH(1, (C5>='Campaign Metadata (2)'!$B$2:$B$10) * (C5<='Campaign Metadata (2)'!$C$2:$C$10), 0)), "No Campaign")} -> No Campaign | Q5: =VLOOKUP(Table1[[#This Row],[Campaign_Name2]],Table3[#All],2,) -> #N/A | R5: =VLOOKUP(Table1[[#This Row],[Campaign_Name2]],Table3[#All],3,FALSE) -> #N/A | S5: =VLOOKUP(Table1[[#This Row],[Campaign_Name2]],Table3[],5,FALSE) -> #N/A | T5: =IF(Table1[[#This Row],[Campaign_Name2]]="No Campaign", 0, Table1[[#This Row],[Budget]]/COUNTIF(Table1[Campaign_Name2],Table1[[#This Row],[Campaign_Name2]])) -> 0
A6: P005 | B6: YouTube | C6: 45469 | D6: Reel | E6: Check out our latest reel on youtube! | F6: 3557 | G6: 687 | H6: 424 | I6: 71140 | J6: 70701 | K6: 224 | L6: #ThirstyForMore,#PepsiCoRefresh | M6: SummerSplash | N6: =SUM(F6,G6,H6) -> 4668 | O6: =IFERROR((Table1[[#This Row],[Likes]]+Table1[[#This Row],[Shares]]+Table1[[#This Row],[Comments]])/Table1[[#This Row],[Impressions]], 0) -> 0.065617093 | P6: {=IFERROR(INDEX('Campaign Metadata (2)'!$A$2:$A$10, MATCH(1, (C6>='Campaign Metadata (2)'!$B$2:$B$10) * (C6<='Campaign Metadata (2)'!$C$2:$C$10), 0)), "No Campaign")} -> SummerSplash | Q6: =VLOOKUP(Table1[[#This Row],[Campaign_Name2]],Table3[#All],2,) -> 45458 | R6: =VLOOKUP(Table1[[#This Row],[Campaign_Name2]],Table3[#All],3,FALSE) -> 45488 | S6: =VLOOKUP(Table1[[#This Row],[Campaign_Name2]],Table3[],5,FALSE) -> 150000 | T6: =IF(Table1[[#This Row],[Campaign_Name2]]="No Campaign", 0, Table1[[#This Row],[Budget]]/COUNTIF(Table1[Campaign_Name2],Table1[[#This Row],[Campaign_Name2]])) -> 5555.5556
A7: P006 | B7: Facebook | C7: 45596 | D7: Carousel | E7: Check out our latest carousel on facebook! | F7: 2945 | G7: 930 | H7: 355 | I7: 23560 | J7: 23275 | K7: 256 | L7: #PepsiCoRefresh | M7: FestiveRadiance | N7: =SUM(F7,G7,H7) -> 4230 | O7: =IFERROR((Table1[[#This Row],[Likes]]+Table1[[#This Row],[Shares]]+Table1[[#This Row],[Comments]])/Table1[[#This Row],[Impressions]], 0) -> 0.1795416 | P7: {=IFERROR(INDEX('Campaign Metadata (2)'!$A$2:$A$10, MATCH(1, (C7>='Campaign Metadata (2)'!$B$2:$B$10) * (C7<='Campaign Metadata (2)'!$C$2:$C$10), 0)), "No Campaign")} -> FestiveRadiance | Q7: =VLOOKUP(Table1[[#This Row],[Campaign_Name2]],Table3[#All],2,) -> 45566 | R7: =VLOOKUP(Table1[[#This Row],[Campaign_Name2]],Table3[#All],3,FALSE) -> 45596 | S7: =VLOOKUP(Table1[[#This Row],[Campaign_Name2]],Table3[],5,FALSE) -> 200000 | T7: =IF(Table1[[#This Row],[Campaign_Name2]]="No Campaign", 0, Table1[[#This Row],[Budget]]/COUNTIF(Table1[Campaign_Name2],Table1[[#This Row],[Campaign_Name2]])) -> 5714.2857
A8: P007 | B8: Twitter | C8: 45467 | D8: Carousel | E8: Check out our latest carousel on twitter! | F8: 3860 | G8: 201 | H8: 279 | I8: 61760 | J8: 61660 | K8: 235 | L8: #PepsiCoRefresh | M8: FestiveRadiance | N8: =SUM(F8,G8,H8) -> 4340 | O8: =IFERROR((Table1[[#This Row],[Likes]]+Table1[[#This Row],[Shares]]+Table1[[#This Row],[Comments]])/Table1[[#This Row],[Impressions]], 0) -> 0.070272021 | P8: {=IFERROR(INDEX('Campaign Metadata (2)'!$A$2:$A$10, MATCH(1, (C8>='Campaign Metadata (2)'!$B$2:$B$10) * (C8<='Campaign Metadata (2)'!$C$2:$C$10), 0)), "No Campaign")} -> SummerSplash | Q8: =VLOOKUP(Table1[[#This Row],[Campaign_Name2]],Table3[#All],2,) -> 45458 | R8: =VLOOKUP(Table1[[#This Row],[Campaign_Name2]],Table3[#All],3,FALSE) -> 45488 | S8: =VLOOKUP(Table1[[#This Row],[Campaign_Name2]],Table3[],5,FALSE) -> 150000 | T8: =IF(Table1[[#This Row],[Campaign_Name2]]="No Campaign", 0, Table1[[#This Row],[Budget]]/COUNTIF(Table1[Campaign_Name2],Table1[[#This Row],[Campaign_Name2]])) -> 5555.5556
A9: P008 | B9: YouTube | C9: 45486 | D9: Image | E9: Check out our latest image on youtube! | F9: 3929 | G9: 262 | H9: 278 | I9: 43219 | J9: 42841 | K9: 39 | L9: #ThirstyForMore | M9: DailyWellness | N9: =SUM(F9,G9,H9) -> 4469 | O9: =IFERROR((Table1[[#This Row],[Likes]]+Table1[[#This Row],[Shares]]+Table1[[#This Row],[Comments]])/Table1[[#This Row],[Impressions]], 0) -> 0.1034036 | P9: {=IFERROR(INDEX('Campaign Metadata (2)'!$A$2:$A$10, MATCH(1, (C9>='Campaign Metadata (2)'!$B$2:$B$10) * (C9<='Campaign Metadata (2)'!$C$2:$C$10), 0)), "No Campaign")} -> SummerSplash | Q9: =VLOOKUP(Table1[[#This Row],[Campaign_Name2]],Table3[#All],2,) -> 45458 | R9: =VLOOKUP(Table1[[#This Row],[Campaign_Name2]],Table3[#All],3,FALSE) -> 45488 | S9: =VLOOKUP(Table1[[#This Row],[Campaign_Name2]],Table3[],5,FALSE) -> 150000 | T9: =IF(Table1[[#This Row],[Campaign_Name2]]="No Campaign", 0, Table1[[#This Row],[Budget]]/COUNTIF(Table1[Campaign_Name2],Table1[[#This Row],[Campaign_Name2]])) -> 5555.5556
A10: P009 | B10: Facebook | C10: 45534 | D10: Text | E10: Check out our latest text on facebook! | F10: 3784 | G10: 808 | H10: 404 | I10: 56760 | J10: 56343 | K10: 131 | L10: #PepsiCoRefresh | M10: FestiveRadiance | N10: =SUM(F10,G10,H10) -> 4996 | O10: =IFERROR((Table1[[#This Row],[Likes]]+Table1[[#This Row],[Shares]]+Table1[[#This Row],[Comments]])/Table1[[#This Row],[Impressions]], 0) -> 0.088019732 | P10: {=IFERROR(INDEX('Campaign Metadata (2)'!$A$2:$A$10, MATCH(1, (C10>='Campaign Metadata (2)'!$B$2:$B$10) * (C10<='Campaign Metadata (2)'!$C$2:$C$10), 0)), "No Campaign")} -> No Campaign | Q10: =VLOOKUP(Table1[[#This Row],[Campaign_Name2]],Table3[#All],2,) -> #N/A | R10: =VLOOKUP(Table1[[#This Row],[Campaign_Name2]],Table3[#All],3,FALSE) -> #N/A | S10: =VLOOKUP(Table1[[#This Row],[Campaign_Name2]],Table3[],5,FALSE) -> #N/A | T10: =IF(Table1[[#This Row],[Campaign_Name2]]="No Campaign", 0, Table1[[#This Row],[Budget]]/COUNTIF(Table1[Campaign_Name2],Table1[[#This Row],[Campaign_Name2]])) -> 0
A11: P010 | B11: Facebook | C11: 45727 | D11: Image | E11: Check out our latest image on facebook! | F11: 4241 | G11: 902 | H11: 47 | I11: 72097 | J11: 71598 | K11: 167 | L11: #PepsiCoRefresh | M11: FestiveRadiance | N11: =SUM(F11,G11,H11) -> 5190 | O11: =IFERROR((Table1[[#This Row],[Likes]]+Table1[[#This Row],[Shares]]+Table1[[#This Row],[Comments]])/Table1[[#This Row],[Impressions]], 0) -> 0.071986352 | P11: {=IFERROR(INDEX('Campaign Metadata (2)'!$A$2:$A$10, MATCH(1, (C11>='Campaign Metadata (2)'!$B$2:$B$10) * (C11<='Campaign Metadata (2)'!$C$2:$C$10), 0)), "No Campaign")} -> DailyWellness | Q11: =VLOOKUP(Table1[[#This Row],[Campaign_Name2]],Table3[#All],2,) -> 45717 | R11: =VLOOKUP(Table1[[#This Row],[Campaign_Name2]],Table3[#All],3,FALSE) -> 45747 | S11: =VLOOKUP(Table1[[#This Row],[Campaign_Name2]],Table3[],5,FALSE) -> 180000 | T11: =IF(Table1[[#This Row],[Campaign_Name2]]="No Campaign", 0, Table1[[#This Row],[Budget]]/COUNTIF(Table1[Campaign_Name2],Table1[[#This Row],[Campaign_Name2]])) -> 5625
A12: P011 | B12: Instagram | C12: 45690 | D12: Story | E12: Check out our latest story on instagram! | F12: 1792 | G12: 614 | H12: 497 | I12: 25088 | J12: 24675 | K12: 65 | L12: #LiveForNow | M12: DailyWellness | N12: =SUM(F12,G12,H12) -> 2903 | O12: =IFERROR((Table1[[#This Row],[Likes]]+Table1[[#This Row],[Shares]]+Table1[[#This Row],[Comments]])/Table1[[#This Row],[Impressions]], 0) -> 0.11571269 | P12: {=IFERROR(INDEX('Campaign Metadata (2)'!$A$2:$A$10, MATCH(1, (C12>='Campaign Metadata (2)'!$B$2:$B$10) * (C12<='Campaign Metadata (2)'!$C$2:$C$10), 0)), "No Campaign")} -> No Campaign | Q12: =VLOOKUP(Table1[[#This Row],[Campaign_Name2]],Table3[#All],2,) -> #N/A | R12: =VLOOKUP(Table1[[#This Row],[Campaign_Name2]],Table3[#All],3,FALSE) -> #N/A | S12: =VLOOKUP(Table1[[#This Row],[Campaign_Name2]],Table3[],5,FALSE) -> #N/A | T12: =IF(Table1[[#This Row],[Campaign_Name2]]="No Campaign", 0, Table1[[#This Row],[Budget]]/COUNTIF(Table1[Campaign_Name2],Table1[[#This Row],[Campaign_Name2]])) -> 0
A13: P012 | B13: Facebook | C13: 45494 | D13: Reel | E13: Check out our latest reel on facebook! | F13: 1946 | G13: 686 | H13: 377 | I13: 23352 | J13: 22982 | K13: 213 | L13: #LiveForNow | M13: NewYearRefresh | N13: =SUM(F13,G13,H13) -> 3009 | O13: =IFERROR((Table1[[#This Row],[Likes]]+Table1[[#This Row],[Shares]]+Table1[[#This Row],[Comments]])/Table1[[#This Row],[Impressions]], 0) -> 0.12885406 | P13: {=IFERROR(INDEX('Campaign Metadata (2)'!$A$2:$A$10, MATCH(1, (C13>='Campaign Metadata (2)'!$B$2:$B$10) * (C13<='Campaign Metadata (2)'!$C$2:$C$10), 0)), "No Campaign")} -> No Campaign | Q13: =VLOOKUP(Table1[[#This Row],[Campaign_Name2]],Table3[#All],2,) -> #N/A | R13: =VLOOKUP(Table1[[#This Row],[Campaign_Name2]],Table3[#All],3,FALSE) -> #N/A | S13: =VLOOKUP(Table1[[#This Row],[Campaign_Name2]],Table3[],5,FALSE) -> #N/A | T13: =IF(Table1[[#This Row],[Campaign_Name2]]="No Campaign", 0, Table1[[#This Row],[Budget]]/COUNTIF(Table1[Campaign_Name2],Table1[[#This Row],[Campaign_Name2]])) -> 0
A14: P013 | B14: YouTube | C14: 45614 | D14: Carousel | E14: Check out our latest carousel on youtube! | F14: 1171 | G14: 286 | H14: 231 | I14: 22249 | J14: 21282 | K14: 114 | L14: #ThirstyForMore | M14: SummerSplash | N14: =SUM(F14,G14,H14) -> 1688 | O14: =IFERROR((Table1[[#This Row],[Likes]]+Table1[[#This Row],[Shares]]+Table1[[#This Row],[Comments]])/Table1[[#This Row],[Impressions]], 0) -> 0.075868578 | P14: {=IFERROR(INDEX('Campaign Metadata (2)'!$A$2:$A$10, MATCH(1, (C14>='Campaign Metadata (2)'!$B$2:$B$10) * (C14<='Campaign Metadata (2)'!$C$2:$C$10), 0)), "No Campaign")} -> No Campaign | Q14: =VLOOKUP(Table1[[#This Row],[Campaign_Name2]],Table3[#All],2,) -> #N/A | R14: =VLOOKUP(Table1[[#This Row],[Campaign_Name2]],Table3[#All],3,FALSE) -> #N/A | S14: =VLOOKUP(Table1[[#This Row],[Campaign_Name2]],Table3[],5,FALSE) -> #N/A | T14: =IF(Table1[[#This Row],[Campaign_Name2]]="No Campaign", 0, Table1[[#This Row],[Budget]]/COUNTIF(Table1[Campaign_Name2],Table1[[#This Row],[Campaign_Name2]])) -> 0
A15: P014 | B15: Facebook | C15: 45704 | D15: Story | E15: Check out our latest story on facebook! | F15: 4242 | G15: 555 | H15: 131 | I15: 33936 | J15: 33802 | K15: 265 | L15: #LiveForNow | N15: =SUM(F15,G15,H15) -> 4928 | O15: =IFERROR((Table1[[#This Row],[Likes]]+Table1[[#This Row],[Shares]]+Table1[[#This Row],[Comments]])/Table1[[#This Row],[Impressions]], 0) -> 0.14521452 | P15: {=IFERROR(INDEX('Campaign Metadata (2)'!$A$2:$A$10, MATCH(1, (C15>='Campaign Metadata (2)'!$B$2:$B$10) * (C15<='Campaign Metadata (2)'!$C$2:$C$10), 0)), "No Campaign")} -> No Campaign | Q15: =VLOOKUP(Table1[[#This Row],[Campaign_Name2]],Table3[#All],2,) -> #N/A | R15: =VLOOKUP(Table1[[#This Row],[Campaign_Name2]],Table3[#All],3,FALSE) -> #N/A | S15: =VLOOKUP(Table1[[#This Row],[Campaign_Name2]],Table3[],5,FALSE) -> #N/A | T15: =IF(Table1[[#This Row],[Campaign_Name2]]="No Campaign", 0, Table1[[#This Row],[Budget]]/COUNTIF(Table1[Campaign_Name2],Table1[[#This Row],[Campaign_Name2]])) -> 0
A16: P015 | B16: Facebook | C16: 45589 | D16: Video | E16: Check out our latest video on facebook! | F16: 3888 | G16: 604 | H16: 128 | I16: 77760 | J16: 77167 | K16: 20 | L16: #LiveForNow | M16: SummerSplash | N16: =SUM(F16,G16,H16) -> 4620 | O16: =IFERROR((Table1[[#This Row],[Likes]]+Table1[[#This Row],[Shares]]+Table1[[#This Row],[Comments]])/Table1[[#This Row],[Impressions]], 0) -> 0.05941358 | P16: {=IFERROR(INDEX('Campaign Metadata (2)'!$A$2:$A$10, MATCH(1, (C16>='Campaign Metadata (2)'!$B$2:$B$10) * (C16<='Campaign Metadata (2)'!$C$2:$C$10), 0)), "No Campaign")} -> FestiveRadiance | Q16: =VLOOKUP(Table1[[#This Row],[Campaign_Name2]],Table3[#All],2,) -> 45566 | R16: =VLOOKUP(Table1[[#This Row],[Campaign_Name2]],Table3[#All],3,FALSE) -> 45596 | S16: =VLOOKUP(Table1[[#This Row],[Campaign_Name2]],Table3[],5,FALSE) -> 200000 | T16: =IF(Table1[[#This Row],[Campaign_Name2]]="No Campaign", 0, Table1[[#This Row],[Budget]]/COUNTIF(Table1[Campaign_Name2],Table1[[#This Row],[Campaign_Name2]])) -> 5714.2857
A17: P016 | B17: Facebook | C17: 45530 | D17: Text | E17: Check out our latest text on facebook! | F17: 3452 | G17: 377 | H17: 360 | I17: 55232 | J17: 55075 | K17: 87 | L17: #LiveForNow | M17: NewYearRefresh | N17: =SUM(F17,G17,H17) -> 4189 | O17: =IFERROR((Table1[[#This Row],[Likes]]+Table1[[#This Row],[Shares]]+Table1[[#This Row],[Comments]])/Table1[[#This Row],[Impressions]], 0) -> 0.075843714 | P17: {=IFERROR(INDEX('Campaign Metadata (2)'!$A$2:$A$10, MATCH(1, (C17>='Campaign Metadata (2)'!$B$2:$B$10) * (C17<='Campaign Metadata (2)'!$C$2:$C$10), 0)), "No Campaign")} -> No Campaign | Q17: =VLOOKUP(Table1[[#This Row],[Campaign_Name2]],Table3[#All],2,) -> #N/A | R17: =VLOOKUP(Table1[[#This Row],[Campaign_Name2]],Table3[#All],3,FALSE) -> #N/A | S17: =VLOOKUP(Table1[[#This Row],[Campaign_Name2]],Table3[],5,FALSE) -> #N/A | T17: =IF(Table1[[#This Row],[Campaign_Name2]]="No Campaign", 0, Table1[[#This Row],[Budget]]/COUNTIF(Table1[Campaign_Name2],Table1[[#This Row],[Campaign_Name2]])) -> 0
A18: P017 | B18: Facebook | C18: 45782 | D18: Text | E18: Check out our latest text on facebook! | F18: 4441 | G18: 511 | H18: 70 | I18: 53292 | J18: 53082 | K18: 159 | L18: #ThirstyForMore | M18: DailyWellness | N18: =SUM(F18,G18,H18) -> 5022 | O18: =IFERROR((Table1[[#This Row],[Likes]]+Table1[[#This Row],[Shares]]+Table1[[#This Row],[Comments]])/Table1[[#This Row],[Impressions]], 0) -> 0.094235533 | P18: {=IFERROR(INDEX('Campaign Metadata (2)'!$A$2:$A$10, MATCH(1, (C18>='Campaign Metadata (2)'!$B$2:$B$10) * (C18<='Campaign Metadata (2)'!$C$2:$C$10), 0)), "No Campaign")} -> No Campaign | Q18: =VLOOKUP(Table1[[#This Row],[Campaign_Name2]],Table3[#All],2,) -> #N/A | R18: =VLOOKUP(Table1[[#This Row],[Campaign_Name2]],Table3[#All],3,FALSE) -> #N/A | S18: =VLOOKUP(Table1[[#This Row],[Campaign_Name2]],Table3[],5,FALSE) -> #N/A | T18: =IF(Table1[[#This Row],[Campaign_Name2]]="No Campaign", 0, Table1[[#This Row],[Budget]]/COUNTIF(Table1[Campaign_Name2],Table1[[#This Row],[Campaign_Name2]])) -> 0
A19: P018 | B19: Instagram | C19: 45523 | D19: Reel | E19: Check out our latest reel on instagram! | F19: 3000 | G19: 382 | H19: 325 | I19: 36000 | J19: 35819 | K19: 19 | L19: #LiveForNow | M19: SummerSplash | N19: =SUM(F19,G19,H19) -> 3707 | O19: =IFERROR((Table1[[#This Row],[Likes]]+Table1[[#This Row],[Shares]]+Table1[[#This Row],[Comments]])/Table1[[#This Row],[Impressions]], 0) -> 0.10297222 | P19: {=IFERROR(INDEX('Campaign Metadata (2)'!$A$2:$A$10, MATCH(1, (C19>='Campaign Metadata (2)'!$B$2:$B$10) * (C19<='Campaign Metadata (2)'!$C$2:$C$10), 0)), "No Campaign")} -> No Campaign | Q19: =VLOOKUP(Table1[[#This Row],[Campaign_Name2]],Table3[#All],2,) -> #N/A | R19: =VLOOKUP(Table1[[#This Row],[Campaign_Name2]],Table3[#All],3,FALSE) -> #N/A | S19: =VLOOKUP(Table1[[#This Row],[Campaign_Name2]],Table3[],5,FALSE) -> #N/A | T19: =IF(Table1[[#This Row],[Campaign_Name2]]="No Campaign", 0, Table1[[#This Row],[Budget]]/COUNTIF(Table1[Campaign_Name2],Table1[[#This Row],[Campaign_Name2]])) -> 0
A20: P019 | B20: Instagram | C20: 45466 | D20: Video | E20: Check out our latest video on instagram! | F20: 1071 | G20: 519 | H20: 22 | I20: 16065 | J20: 15865 | K20: 103 | L20: #PepsiCoRefresh | M20: DailyWellness | N20: =SUM(F20,G20,H20) -> 1612 | O20: =IFERROR((Table1[[#This Row],[Likes]]+Table1[[#This Row],[Shares]]+Table1[[#This Row],[Comments]])/Table1[[#This Row],[Impressions]], 0) -> 0.10034236 | P20: {=IFERROR(INDEX('Campaign Metadata (2)'!$A$2:$A$10, MATCH(1, (C20>='Campaign Metadata (2)'!$B$2:$B$10) * (C20<='Campaign Metadata (2)'!$C$2:$C$10), 0)), "No Campaign")} -> SummerSplash | Q20: =VLOOKUP(Table1[[#This Row],[Campaign_Name2]],Table3[#All],2,) -> 45458 | R20: =VLOOKUP(Table1[[#This Row],[Campaign_Name2]],Table3[#All],3,FALSE) -> 45488 | S20: =VLOOKUP(Table1[[#This Row],[Campaign_Name2]],Table3[],5,FALSE) -> 150000 | T20: =IF(Table1[[#This Row],[Campaign_Name2]]="No Campaign", 0, Table1[[#This Row],[Budget]]/COUNTIF(Table1[Campaign_Name2],Table1[[#This Row],[Campaign_Name2]])) -> 5555.5556
A21: P020 | B21: Instagram | C21: 45544 | D21: Carousel | E21: Check out our latest carousel on instagram! | F21: 4054 | G21: 488 | H21: 373 | I21: 77026 | J21: 76881 | K21: 25 | L21: #PepsiCoRefresh | M21: SummerSplash | N21: =SUM(F21,G21,H21) -> 4915 | O21: =IFERROR((Table1[[#This Row],[Likes]]+Table1[[#This Row],[Shares]]+Table1[[#This Row],[Comments]])/Table1[[#This Row],[Impressions]], 0) -> 0.063809623 | P21: {=IFERROR(INDEX('Campaign Metadata (2)'!$A$2:$A$10, MATCH(1, (C21>='Campaign Metadata (2)'!$B$2:$B$10) * (C21<='Campaign Metadata (2)'!$C$2:$C$10), 0)), "No Campaign")} -> No Campaign | Q21: =VLOOKUP(Table1[[#This Row],[Campaign_Name2]],Table3[#All],2,) -> #N/A | R21: =VLOOKUP(Table1[[#This Row],[Campaign_Name2]],Table3[#All],3,FALSE) -> #N/A | S21: =VLOOKUP(Table1[[#This Row],[Campaign_Name2]],Table3[],5,FALSE) -> #N/A | T21: =IF(Table1[[#This Row],[Campaign_Name2]]="No Campaign", 0, Table1[[#This Row],[Budget]]/COUNTIF(Table1[Campaign_Name2],Table1[[#This Row],[Campaign_Name2]])) -> 0
A22: P021 | B22: Instagram | C22: 45661 | D22: Reel | E22: Check out our latest reel on instagram! | F22: 4838 | G22: 640 | H22: 128 | I22: 72570 | J22: 72396 | K22: 83 | L22: #LiveForNow | M22: DailyWellness | N22: =SUM(F22,G22,H22) -> 5606 | O22: =IFERROR((Table1[[#This Row],[Likes]]+Table1[[#This Row],[Shares]]+Table1[[#This Row],[Comments]])/Table1[[#This Row],[Impressions]], 0) -> 0.077249552 | P22: {=IFERROR(INDEX('Campaign Metadata (2)'!$A$2:$A$10, MATCH(1, (C22>='Campaign Metadata (2)'!$B$2:$B$10) * (C22<='Campaign Metadata (2)'!$C$2:$C$10), 0)), "No Campaign")} -> NewYearRefresh | Q22: =VLOOKUP(Table1[[#This Row],[Campaign_Name2]],Table3[#All],2,) -> 45651 | R22: =VLOOKUP(Table1[[#This Row],[Campaign_Name2]],Table3[#All],3,FALSE) -> 45667 | S22: =VLOOKUP(Table1[[#This Row],[Campaign_Name2]],Table3[],5,FALSE) -> 250000 | T22: =IF(Table1[[#This Row],[Campaign_Name2]]="No Campaign", 0, Table1[[#This Row],[Budget]]/COUNTIF(Table1[Campaign_Name2],Table1[[#This Row],[Campaign_Name2]])) -> 25000
A23: P022 | B23: Facebook | C23: 45715 | D23: Text | E23: Check out our latest text on facebook! | F23: 1570 | G23: 187 | H23: 260 | I23: 25120 | J23: 24613 | K23: 133 | L23: #PepsiCoRefresh | M23: DailyWellness | N23: =SUM(F23,G23,H23) -> 2017 | O23: =IFERROR((Table1[[#This Row],[Likes]]+Table1[[#This Row],[Shares]]+Table1[[#This Row],[Comments]])/Table1[[#This Row],[Impressions]], 0) -> 0.080294586 | P23: {=IFERROR(INDEX('Campaign Metadata (2)'!$A$2:$A$10, MATCH(1, (C23>='Campaign Metadata (2)'!$B$2:$B$10) * (C23<='Campaign Metadata (2)'!$C$2:$C$10), 0)), "No Campaign")} -> No Campaign | Q23: =VLOOKUP(Table1[[#This Row],[Campaign_Name2]],Table3[#All],2,) -> #N/A | R23: =VLOOKUP(Table1[[#This Row],[Campaign_Name2]],Table3[#All],3,FALSE) -> #N/A | S23: =VLOOKUP(Table1[[#This Row],[Campaign_Name2]],Table3[],5,FALSE) -> #N/A | T23: =IF(Table1[[#This Row],[Campaign_Name2]]="No Campaign", 0, Table1[[#This Row],[Budget]]/COUNTIF(Table1[Campaign_Name2],Table1[[#This Row],[Campaign_Name2]])) -> 0
A24: P023 | B24: Facebook | C24: 45602 | D24: Video | E24: Check out our latest video on facebook! | F24: 1606 | G24: 547 | H24: 316 | I24: 32120 | J24: 31736 | K24: 225 | L24: #PepsiCoRefresh,#AnytimeIsPepsiTime | M24: FestiveRadiance | N24: =SUM(F24,G24,H24) -> 2469 | O24: =IFERROR((Table1[[#This Row],[Likes]]+Table1[[#This Row],[Shares]]+Table1[[#This Row],[Comments]])/Table1[[#This Row],[Impressions]], 0) -> 0.076867995 | P24: {=IFERROR(INDEX('Campaign Metadata (2)'!$A$2:$A$10, MATCH(1, (C24>='Campaign Metadata (2)'!$B$2:$B$10) * (C24<='Campaign Metadata (2)'!$C$2:$C$10), 0)), "No Campaign")} -> No Campaign | Q24: =VLOOKUP(Table1[[#This Row],[Campaign_Name2]],Table3[#All],2,) -> #N/A | R24: =VLOOKUP(Table1[[#This Row],[Campaign_Name2]],Table3[#All],3,FALSE) -> #N/A | S24: =VLOOKUP(Table1[[#This Row],[Campaign_Name2]],Table3[],5,FALSE) -> #N/A | T24: =IF(Table1[[#This Row],[Campaign_Name2]]="No Campaign", 0, Table1[[#This Row],[Budget]]/COUNTIF(Table1[Campaign_Name2],Table1[[#This Row],[Campaign_Name2]])) -> 0
A25: P024 | B25: Facebook | C25: 45680 | D25: Video | E25: Check out our latest video on facebook! | F25: 3961 | G25: 761 | H25: 131 | I25: 67337 | J25: 66615 | K25: 161 | L25: #LiveForNow | M25: NewYearRefresh | N25: =SUM(F25,G25,H25) -> 4853 | O25: =IFERROR((Table1[[#This Row],[Likes]]+Table1[[#This Row],[Shares]]+Table1[[#This Row],[Comments]])/Table1[[#This Row],[Impressions]], 0) -> 0.072070333 | P25: {=IFERROR(INDEX('Campaign Metadata (2)'!$A$2:$A$10, MATCH(1, (C25>='Campaign Metadata (2)'!$B$2:$B$10) * (C25<='Campaign Metadata (2)'!$C$2:$C$10), 0)), "No Campaign")} -> No Campaign | Q25: =VLOOKUP(Table1[[#This Row],[Campaign_Name2]],Table3[#All],2,) -> #N/A | R25: =VLOOKUP(Table1[[#This Row],[Campaign_Name2]],Table3[#All],3,FALSE) -> #N/A | S25: =VLOOKUP(Table1[[#This Row],[Campaign_Name2]],Table3[],5,FALSE) -> #N/A | T25: =IF(Table1[[#This Row],[Campaign_Name2]]="No Campaign", 0, Table1[[#This Row],[Budget]]/COUNTIF(Table1[Campaign_Name2],Table1[[#This Row],[Campaign_Name2]])) -> 0
A26: P025 | B26: Twitter | C26: 45757 | D26: Carousel | E26: Check out our latest carousel on twitter! | F26: 3128 | G26: 211 | H26: 197 | I26: 59432 | J26: 59182 | K26: 238 | L26: #ThirstyForMore | N26: =SUM(F26,G26,H26) -> 3536 | O26: =IFERROR((Table1[[#This Row],[Likes]]+Table1[[#This Row],[Shares]]+Table1[[#This Row],[Comments]])/Table1[[#This Row],[Impressions]], 0) -> 0.059496568 | P26: {=IFERROR(INDEX('Campaign Metadata (2)'!$A$2:$A$10, MATCH(1, (C26>='Campaign Metadata (2)'!$B$2:$B$10) * (C26<='Campaign Metadata (2)'!$C$2:$C$10), 0)), "No Campaign")} -> No Campaign | Q26: =VLOOKUP(Table1[[#This Row],[Campaign_Name2]],Table3[#All],2,) -> #N/A | R26: =VLOOKUP(Table1[[#This Row],[Campaign_Name2]],Table3[#All],3,FALSE) -> #N/A | S26: =VLOOKUP(Table1[[#This Row],[Campaign_Name2]],Table3[],5,FALSE) -> #N/A | T26: =IF(Table1[[#This Row],[Campaign_Name2]]="No Campaign", 0, Table1[[#This Row],[Budget]]/COUNTIF(Table1[Campaign_Name2],Table1[[#This Row],[Campaign_Name2]])) -> 0
A27: P026 | B27: YouTube | C27: 45752 | D27: Reel | E27: Check out our latest reel on youtube! | F27: 3009 | G27: 413 | H27: 358 | I27: 42126 | J27: 41309 | K27: 211 | L27: #LiveForNow | M27: FestiveRadiance | N27: =SUM(F27,G27,H27) -> 3780 | O27: =IFERROR((Table1[[#This Row],[Likes]]+Table1[[#This Row],[Shares]]+Table1[[#This Row],[Comments]])/Table1[[#This Row],[Impressions]], 0) -> 0.089730808 | P27: {=IFERROR(INDEX('Campaign Metadata (2)'!$A$2:$A$10, MATCH(1, (C27>='Campaign Metadata (2)'!$B$2:$B$10) * (C27<='Campaign Metadata (2)'!$C$2:$C$10), 0)), "No Campaign")} -> No Campaign | Q27: =VLOOKUP(Table1[[#This Row],[Campaign_Name2]],Table3[#All],2,) -> #N/A | R27: =VLOOKUP(Table1[[#This Row],[Campaign_Name2]],Table3[#All],3,FALSE) -> #N/A | S27: =VLOOKUP(Table1[[#This Row],[Campaign_Name2]],Table3[],5,FALSE) -> #N/A | T27: =IF(Table1[[#This Row],[Campaign_Name2]]="No Campaign", 0, Table1[[#This Row],[Budget]]/COUNTIF(Table1[Campaign_Name2],Table1[[#This Row],[Campaign_Name2]])) -> 0
A28: P027 | B28: YouTube | C28: 45552 | D28: Text | E28: Check out our latest text on youtube! | F28: 2076 | G28: 195 | H28: 104 | I28: 33216 | J28: 32244 | K28: 51 | L28: #LiveForNow | M28: DailyWellness | N28: =SUM(F28,G28,H28) -> 2375 | O28: =IFERROR((Table1[[#This Row],[Likes]]+Table1[[#This Row],[Shares]]+Table1[[#This Row],[Comments]])/Table1[[#This Row],[Impressions]], 0) -> 0.071501686 | P28: {=IFERROR(INDEX('Campaign Metadata (2)'!$A$2:$A$10, MATCH(1, (C28>='Campaign Metadata (2)'!$B$2:$B$10) * (C28<='Campaign Metadata (2)'!$C$2:$C$10), 0)), "No Campaign")} -> No Campaign | Q28: =VLOOKUP(Table1[[#This Row],[Campaign_Name2]],Table3[#All],2,) -> #N/A | R28: =VLOOKUP(Table1[[#This Row],[Campaign_Name2]],Table3[#All],3,FALSE) -> #N/A | S28: =VLOOKUP(Table1[[#This Row],[Campaign_Name2]],Table3[],5,FALSE) -> #N/A | T28: =IF(Table1[[#This Row],[Campaign_Name2]]="No Campaign", 0, Table1[[#This Row],[Budget]]/COUNTIF(Table1[Campaign_Name2],Table1[[#This Row],[Campaign_Name2]])) -> 0
A29: P028 | B29: Instagram | C29: 45720 | D29: Video | E29: Check out our latest video on instagram! | F29: 432 | G29: 624 | H29: 123 | I29: 6912 | J29: 6259 | K29: 79 | L29: #LiveForNow | M29: DailyWellness | N29: =SUM(F29,G29,H29) -> 1179 | O29: =IFERROR((Table1[[#This Row],[Likes]]+Table1[[#This Row],[Shares]]+Table1[[#This Row],[Comments]])/Table1[[#This Row],[Impressions]], 0) -> 0.17057292 | P29: {=IFERROR(INDEX('Campaign Metadata (2)'!$A$2:$A$10, MATCH(1, (C29>='Campaign Metadata (2)'!$B$2:$B$10) * (C29<='Campaign Metadata (2)'!$C$2:$C$10), 0)), "No Campaign")} -> DailyWellness | Q29: =VLOOKUP(Table1[[#This Row],[Campaign_Name2]],Table3[#All],2,) -> 45717 | R29: =VLOOKUP(Table1[[#This Row],[Campaign_Name2]],Table3[#All],3,FALSE) -> 45747 | S29: =VLOOKUP(Table1[[#This Row],[Campaign_Name2]],Table3[],5,FALSE) -> 180000 | T29: =IF(Table1[[#This Row],[Campaign_Name2]]="No Campaign", 0, Table1[[#This Row],[Budget]]/COUNTIF(Table1[Campaign_Name2],Table1[[#This Row],[Campaign_Name2]])) -> 5625
A30: P029 | B30: Instagram | C30: 45688 | D30: Carousel | E30: Check out our latest carousel on instagram! | F30: 2566 | G30: 118 | H30: 37 | I30: 12830 | J30: 12264 | K30: 221 | L30: #LiveForNow | M30: NewYearRefresh | N30: =SUM(F30,G30,H30) -> 2721 | O30: =IFERROR((Table1[[#This Row],[Likes]]+Table1[[#This Row],[Shares]]+Table1[[#This Row],[Comments]])/Table1[[#This Row],[Impressions]], 0) -> 0.21208106 | P30: {=IFERROR(INDEX('Campaign Metadata (2)'!$A$2:$A$10, MATCH(1, (C30>='Campaign Metadata (2)'!$B$2:$B$10) * (C30<='Campaign Metadata (2)'!$C$2:$C$10), 0)), "No Campaign")} -> No Campaign | Q30: =VLOOKUP(Table1[[#This Row],[Campaign_Name2]],Table3[#All],2,) -> #N/A | R30: =VLOOKUP(Table1[[#This Row],[Campaign_Name2]],Table3[#All],3,FALSE) -> #N/A | S30: =VLOOKUP(Table1[[#This Row],[Campaign_Name2]],Table3[],5,FALSE) -> #N/A | T30: =IF(Table1[[#This Row],[Campaign_Name2]]="No Campaign", 0, Table1[[#This Row],[Budget]]/COUNTIF(Table1[Campaign_Name2],Table1[[#This Row],[Campaign_Name2]])) -> 0
A31: P030 | B31: Instagram | C31: 45713 | D31: Video | E31: Check out our latest video on instagram! | F31: 3095 | G31: 39 | H31: 78 | I31: 55710 | J31: 54808 | K31: 93 | L31: #ThirstyForMore | N31: =SUM(F31,G31,H31) -> 3212 | O31: =IFERROR((Table1[[#This Row],[Likes]]+Table1[[#This Row],[Shares]]+Table1[[#This Row],[Comments]])/Table1[[#This Row],[Impressions]], 0) -> 0.057655717 | P31: {=IFERROR(INDEX('Campaign Metadata (2)'!$A$2:$A$10, MATCH(1, (C31>='Campaign Metadata (2)'!$B$2:$B$10) * (C31<='Campaign Metadata (2)'!$C$2:$C$10), 0)), "No Campaign")} -> No Campaign | Q31: =VLOOKUP(Table1[[#This Row],[Campaign_Name2]],Table3[#All],2,) -> #N/A | R31: =VLOOKUP(Table1[[#This Row],[Campaign_Name2]],Table3[#All],3,FALSE) -> #N/A | S31: =VLOOKUP(Table1[[#This Row],[Campaign_Name2]],Table3[],5,FALSE) -> #N/A | T31: =IF(Table1[[#This Row],[Campaign_Name2]]="No Campaign", 0, Table1[[#This Row],[Budget]]/COUNTIF(Table1[Campaign_Name2],Table1[[#This Row],[Campaign_Name2]])) -> 0
A32: P031 | B32: Instagram | C32: 45642 | D32: Text | E32: Check out our latest text on instagram! | F32: 438 | G32: 153 | H32: 275 | I32: 3066 | J32: 2701 | K32: 282 | L32: #PepsiCoRefresh | M32: FestiveRadiance | N32: =SUM(F32,G32,H32) -> 866 | O32: =IFERROR((Table1[[#This Row],[Likes]]+Table1[[#This Row],[Shares]]+Table1[[#This Row],[Comments]])/Table1[[#This Row],[Impressions]], 0) -> 0.28245271 | P32: {=IFERROR(INDEX('Campaign Metadata (2)'!$A$2:$A$10, MATCH(1, (C32>='Campaign Metadata (2)'!$B$2:$B$10) * (C32<='Campaign Metadata (2)'!$C$2:$C$10), 0)), "No Campaign")} -> No Campaign | Q32: =VLOOKUP(Table1[[#This Row],[Campaign_Name2]],Table3[#All],2,) -> #N/A | R32: =VLOOKUP(Table1[[#This Row],[Campaign_Name2]],Table3[#All],3,FALSE) -> #N/A | S32: =VLOOKUP(Table1[[#This Row],[Campaign_Name2]],Table3[],5,FALSE) -> #N/A | T32: =IF(Table1[[#This Row],[Campaign_Name2]]="No Campaign", 0, Table1[[#This Row],[Budget]]/COUNTIF(Table1[Campaign_Name2],Table1[[#This Row],[Campaign_Name2]])) -> 0
A33: P032 | B33: Twitter | C33: 45504 | D33: Carousel | E33: Check out our latest carousel on twitter! | F33: 2278 | G33: 10 | H33: 321 | I33: 13668 | J33: 12676 | K33: 275 | L33: #ThirstyForMore | M33: SummerSplash | N33: =SUM(F33,G33,H33) -> 2609 | O33: =IFERROR((Table1[[#This Row],[Likes]]+Table1[[#This Row],[Shares]]+Table1[[#This Row],[Comments]])/Table1[[#This Row],[Impressions]], 0) -> 0.19088382 | P33: {=IFERROR(INDEX('Campaign Metadata (2)'!$A$2:$A$10, MATCH(1, (C33>='Campaign Metadata (2)'!$B$2:$B$10) * (C33<='Campaign Metadata (2)'!$C$2:$C$10), 0)), "No Campaign")} -> No Campaign | Q33: =VLOOKUP(Table1[[#This Row],[Campaign_Name2]],Table3[#All],2,) -> #N/A | R33: =VLOOKUP(Table1[[#This Row],[Campaign_Name2]],Table3[#All],3,FALSE) -> #N/A | S33: =VLOOKUP(Table1[[#This Row],[Campaign_Name2]],Table3[],5,FALSE) -> #N/A | T33: =IF(Table1[[#This Row],[Campaign_Name2]]="No Campaign", 0, Table1[[#This Row],[Budget]]/COUNTIF(Table1[Campaign_Name2],Table1[[#This Row],[Campaign_Name2]])) -> 0
A34: P033 | B34: Facebook | C34: 45525 | D34: Image | E34: Check out our latest image on facebook! | F34: 1407 | G34: 400 | H34: 351 | I34: 16884 | J34: 15954 | K34: 113 | L34: #PepsiCoRefresh | M34: SummerSplash | N34: =SUM(F34,G34,H34) -> 2158 | O34: =IFERROR((Table1[[#This Row],[Likes]]+Table1[[#This Row],[Shares]]+Table1[[#This Row],[Comments]])/Table1[[#This Row],[Impressions]], 0) -> 0.12781331 | P34: {=IFERROR(INDEX('Campaign Metadata (2)'!$A$2:$A$10, MATCH(1, (C34>='Campaign Metadata (2)'!$B$2:$B$10) * (C34<='Campaign Metadata (2)'!$C$2:$C$10), 0)), "No Campaign")} -> No Campaign | Q34: =VLOOKUP(Table1[[#This Row],[Campaign_Name2]],Table3[#All],2,) -> #N/A | R34: =VLOOKUP(Table1[[#This Row],[Campaign_Name2]],Table3[#All],3,FALSE) -> #N/A | S34: =VLOOKUP(Table1[[#This Row],[Campaign_Name2]],Table3[],5,FALSE) -> #N/A | T34: =IF(Table1[[#This Row],[Campaign_Name2]]="No Campaign", 0, Table1[[#This Row],[Budget]]/COUNTIF(Table1[Campaign_Name2],Table1[[#This Row],[Campaign_Name2]])) -> 0
A35: P034 | B35: Facebook | C35: 45742 | D35: Text | E35: Check out our latest text on facebook! | F35: 1652 | G35: 89 | H35: 357 | I35: 29736 | J35: 28771 | K35: 215 | L35: #PepsiCoRefresh | M35: NewYearRefresh | N35: =SUM(F35,G35,H35) -> 2098 | O35: =IFERROR((Table1[[#This Row],[Likes]]+Table1[[#This Row],[Shares]]+Table1[[#This Row],[Comments]])/Table1[[#This Row],[Impressions]], 0) -> 0.07055421 | P35: {=IFERROR(INDEX('Campaign Metadata (2)'!$A$2:$A$10, MATCH(1, (C35>='Campaign Metadata (2)'!$B$2:$B$10) * (C35<='Campaign Metadata (2)'!$C$2:$C$10), 0)), "No Campaign")} -> DailyWellness | Q35: =VLOOKUP(Table1[[#This Row],[Campaign_Name2]],Table3[#All],2,) -> 45717 | R35: =VLOOKUP(Table1[[#This Row],[Campaign_Name2]],Table3[#All],3,FALSE) -> 45747 | S35: =VLOOKUP(Table1[[#This Row],[Campaign_Name2]],Table3[],5,FALSE) -> 180000 | T35: =IF(Table1[[#This Row],[Campaign_Name2]]="No Campaign", 0, Table1[[#This Row],[Budget]]/COUNTIF(Table1[Campaign_Name2],Table1[[#This Row],[Campaign_Name2]])) -> 5625
A36: P035 | B36: Instagram | C36: 45626 | D36: Video | E36: Check out our latest video on instagram! | F36: 3775 | G36: 16 | H36: 239 | I36: 33975 | J36: 33310 | K36: 271 | L36: #LiveForNow | M36: FestiveRadiance | N36: =SUM(F36,G36,H36) -> 4030 | O36: =IFERROR((Table1[[#This Row],[Likes]]+Table1[[#This Row],[Shares]]+Table1[[#This Row],[Comments]])/Table1[[#This Row],[Impressions]], 0) -> 0.11861663 | P36: {=IFERROR(INDEX('Campaign Metadata (2)'!$A$2:$A$10, MATCH(1, (C36>='Campaign Metadata (2)'!$B$2:$B$10) * (C36<='Campaign Metadata (2)'!$C$2:$C$10), 0)), "No Campaign")} -> No Campaign | Q36: =VLOOKUP(Table1[[#This Row],[Campaign_Name2]],Table3[#All],2,) -> #N/A | R36: =VLOOKUP(Table1[[#This Row],[Campaign_Name2]],Table3[#All],3,FALSE) -> #N/A | S36: =VLOOKUP(Table1[[#This Row],[Campaign_Name2]],Table3[],5,FALSE) -> #N/A | T36: =IF(Table1[[#This Row],[Campaign_Name2]]="No Campaign", 0, Table1[[#This Row],[Budget]]/COUNTIF(Table1[Campaign_Name2],Table1[[#This Row],[Campaign_Name2]])) -> 0
A37: P036 | B37: Instagram | C37: 45766 | D37: Story | E37: Check out our latest story on instagram! | F37: 4518 | G37: 285 | H37: 383 | I37: 67770 | J37: 67621 | K37: 31 | L37: #ThirstyForMore | M37: FestiveRadiance | N37: =SUM(F37,G37,H37) -> 5186 | O37: =IFERROR((Table1[[#This Row],[Likes]]+Table1[[#This Row],[Shares]]+Table1[[#This Row],[Comments]])/Table1[[#This Row],[Impressions]], 0) -> 0.076523535 | P37: {=IFERROR(INDEX('Campaign Metadata (2)'!$A$2:$A$10, MATCH(1, (C37>='Campaign Metadata (2)'!$B$2:$B$10) * (C37<='Campaign Metadata (2)'!$C$2:$C$10), 0)), "No Campaign")} -> No Campaign | Q37: =VLOOKUP(Table1[[#This Row],[Campaign_Name2]],Table3[#All],2,) -> #N/A | R37: =VLOOKUP(Table1[[#This Row],[Campaign_Name2]],Table3[#All],3,FALSE) -> #N/A | S37: =VLOOKUP(Table1[[#This Row],[Campaign_Name2]],Table3[],5,FALSE) -> #N/A | T37: =IF(Table1[[#This Row],[Campaign_Name2]]="No Campaign", 0, Table1[[#This Row],[Budget]]/COUNTIF(Table1[Campaign_Name2],Table1[[#This Row],[Campaign_Name2]])) -> 0
A38: P037 | B38: Facebook | C38: 45663 | D38: Carousel | E38: Check out our latest carousel on facebook! | F38: 3024 | G38: 925 | H38: 350 | I38: 24192 | J38: 23518 | K38: 36 | L38: #ThirstyForMore | M38: FestiveRadiance | N38: =SUM(F38,G38,H38) -> 4299 | O38: =IFERROR((Table1[[#This Row],[Likes]]+Table1[[#This Row],[Shares]]+Table1[[#This Row],[Comments]])/Table1[[#This Row],[Impressions]], 0) -> 0.17770337 | P38: {=IFERROR(INDEX('Campaign Metadata (2)'!$A$2:$A$10, MATCH(1, (C38>='Campaign Metadata (2)'!$B$2:$B$10) * (C38<='Campaign Metadata (2)'!$C$2:$C$10), 0)), "No Campaign")} -> NewYearRefresh | Q38: =VLOOKUP(Table1[[#This Row],[Campaign_Name2]],Table3[#All],2,) -> 45651 | R38: =VLOOKUP(Table1[[#This Row],[Campaign_Name2]],Table3[#All],3,FALSE) -> 45667 | S38: =VLOOKUP(Table1[[#This Row],[Campaign_Name2]],Table3[],5,FALSE) -> 250000 | T38: =IF(Table1[[#This Row],[Campaign_Name2]]="No Campaign", 0, Table1[[#This Row],[Budget]]/COUNTIF(Table1[Campaign_Name2],Table1[[#This Row],[Campaign_Name2]])) -> 25000
A39: P038 | B39: YouTube | C39: 45705 | D39: Reel | E39: Check out our latest reel on youtube! | F39: 3138 | G39: 123 | H39: 291 | I39: 28242 | J39: 27550 | K39: 87 | L39: #PepsiCoRefresh | M39: DailyWellness | N39: =SUM(F39,G39,H39) -> 3552 | O39: =IFERROR((Table1[[#This Row],[Likes]]+Table1[[#This Row],[Shares]]+Table1[[#This Row],[Comments]])/Table1[[#This Row],[Impressions]], 0) -> 0.12577013 | P39: {=IFERROR(INDEX('Campaign Metadata (2)'!$A$2:$A$10, MATCH(1, (C39>='Campaign Metadata (2)'!$B$2:$B$10) * (C39<='Campaign Metadata (2)'!$C$2:$C$10), 0)), "No Campaign")} -> No Campaign | Q39: =VLOOKUP(Table1[[#This Row],[Campaign_Name2]],Table3[#All],2,) -> #N/A | R39: =VLOOKUP(Table1[[#This Row],[Campaign_Name2]],Table3[#All],3,FALSE) -> #N/A | S39: =VLOOKUP(Table1[[#This Row],[Campaign_Name2]],Table3[],5,FALSE) -> #N/A | T39: =IF(Table1[[#This Row],[Campaign_Name2]]="No Campaign", 0, Table1[[#This Row],[Budget]]/COUNTIF(Table1[Campaign_Name2],Table1[[#This Row],[Campaign_Name2]])) -> 0
A40: P039 | B40: Facebook | C40: 45621 | D40: Image | E40: Check out our latest image on facebook! | F40: 3564 | G40: 629 | H40: 177 | I40: 60588 | J40: 59627 | K40: 92 | L40: #PepsiCoRefresh | N40: =SUM(F40,G40,H40) -> 4370 | O40: =IFERROR((Table1[[#This Row],[Likes]]+Table1[[#This Row],[Shares]]+Table1[[#This Row],[Comments]])/Table1[[#This Row],[Impressions]], 0) -> 0.072126494 | P40: {=IFERROR(INDEX('Campaign Metadata (2)'!$A$2:$A$10, MATCH(1, (C40>='Campaign Metadata (2)'!$B$2:$B$10) * (C40<='Campaign Metadata (2)'!$C$2:$C$10), 0)), "No Campaign")} -> No Campaign | Q40: =VLOOKUP(Table1[[#This Row],[Campaign_Name2]],Table3[#All],2,) -> #N/A | R40: =VLOOKUP(Table1[[#This Row],[Campaign_Name2]],Table3[#All],3,FALSE) -> #N/A | S40: =VLOOKUP(Table1[[#This Row],[Campaign_Name2]],Table3[],5,FALSE) -> #N/A | T40: =IF(Table1[[#This Row],[Campaign_Name2]]="No Campaign", 0, Table1[[#This Row],[Budget]]/COUNTIF(Table1[Campaign_Name2],Table1[[#This Row],[Campaign_Name2]])) -> 0
...

Sheet Clean_Hashtag_Data
A1: Post ID | B1: Platform | C1: Date | D1: Content Type | E1: Post Text | F1: Likes | G1: Shares | H1: Comments | I1: Impressions | J1: Reach | K1: Clicks | L1: Hashtags Used | M1: Campaign_Name | N1: Total Engagement | O1: Engagement Rate | P1: Campaign_Name2 | Q1: Start Date | R1: End Date | S1: Budget
A2: P001 | B2: Twitter | C2: 45649 | D2: Reel | E2: Check out our latest reel on twitter! | F2: 1461 | G2: 184 | H2: 344 | I2: 21915 | J2: 21675 | K2: 15 | L2: #LiveForNow | M2: SummerSplash | N2: 1989 | O2: 0.090759754 | P2: No Campaign
A3: P001 | B3: Twitter | C3: 45649 | D3: Reel | E3: Check out our latest reel on twitter! | F3: 1461 | G3: 184 | H3: 344 | I3: 21915 | J3: 21675 | K3: 15 | L3: #AnytimeIsPepsiTime | M3: SummerSplash | N3: 1989 | O3: 0.090759754 | P3: No Campaign
A4: P002 | B4: Twitter | C4: 45750 | D4: Text | E4: Check out our latest text on twitter! | F4: 4054 | G4: 389 | H4: 493 | I4: 64864 | J4: 64383 | K4: 117 | L4: #PepsiCoRefresh | M4: FestiveRadiance | N4: 4936 | O4: 0.076097681 | P4: No Campaign
A5: P002 | B5: Twitter | C5: 45750 | D5: Text | E5: Check out our latest text on twitter! | F5: 4054 | G5: 389 | H5: 493 | I5: 64864 | J5: 64383 | K5: 117 | L5: #BetterWithPepsi | M5: FestiveRadiance | N5: 4936 | O5: 0.076097681 | P5: No Campaign
A6: P003 | B6: YouTube | C6: 45789 | D6: Reel | E6: Check out our latest reel on youtube! | F6: 2795 | G6: 105 | H6: 49 | I6: 53105 | J6: 52307 | K6: 204 | L6: #PepsiCoRefresh | M6: NewYearRefresh | N6: 2949 | O6: 0.055531494 | P6: No Campaign
A7: P004 | B7: Instagram | C7: 45516 | D7: Story | E7: Check out our latest story on instagram! | F7: 2404 | G7: 363 | H7: 138 | I7: 19232 | J7: 18636 | K7: 128 | L7: #ThirstyForMore | M7: DailyWellness | N7: 2905 | O7: 0.15105033 | P7: No Campaign
A8: P005 | B8: YouTube | C8: 45469 | D8: Reel | E8: Check out our latest reel on youtube! | F8: 3557 | G8: 687 | H8: 424 | I8: 71140 | J8: 70701 | K8: 224 | L8: #ThirstyForMore | M8: SummerSplash | N8: 4668 | O8: 0.065617093 | P8: SummerSplash | Q8: 45458 | R8: 45488 | S8: 150000
A9: P005 | B9: YouTube | C9: 45469 | D9: Reel | E9: Check out our latest reel on youtube! | F9: 3557 | G9: 687 | H9: 424 | I9: 71140 | J9: 70701 | K9: 224 | L9: #PepsiCoRefresh | M9: SummerSplash | N9: 4668 | O9: 0.065617093 | P9: SummerSplash | Q9: 45458 | R9: 45488 | S9: 150000
A10: P006 | B10: Facebook | C10: 45596 | D10: Carousel | E10: Check out our latest carousel on facebook! | F10: 2945 | G10: 930 | H10: 355 | I10: 23560 | J10: 23275 | K10: 256 | L10: #PepsiCoRefresh | M10: FestiveRadiance | N10: 4230 | O10: 0.1795416 | P10: FestiveRadiance | Q10: 45566 | R10: 45596 | S10: 200000
A11: P007 | B11: Twitter | C11: 45467 | D11: Carousel | E11: Check out our latest carousel on twitter! | F11: 3860 | G11: 201 | H11: 279 | I11: 61760 | J11: 61660 | K11: 235 | L11: #PepsiCoRefresh | M11: FestiveRadiance | N11: 4340 | O11: 0.070272021 | P11: SummerSplash | Q11: 45458 | R11: 45488 | S11: 150000
A12: P008 | B12: YouTube | C12: 45486 | D12: Image | E12: Check out our latest image on youtube! | F12: 3929 | G12: 262 | H12: 278 | I12: 43219 | J12: 42841 | K12: 39 | L12: #ThirstyForMore | M12: DailyWellness | N12: 4469 | O12: 0.1034036 | P12: SummerSplash | Q12: 45458 | R12: 45488 | S12: 150000
A13: P009 | B13: Facebook | C13: 45534 | D13: Text | E13: Check out our latest text on facebook! | F13: 3784 | G13: 808 | H13: 404 | I13: 56760 | J13: 56343 | K13: 131 | L13: #PepsiCoRefresh | M13: FestiveRadiance | N13: 4996 | O13: 0.088019732 | P13: No Campaign
A14: P010 | B14: Facebook | C14: 45727 | D14: Image | E14: Check out our latest image on facebook! | F14: 4241 | G14: 902 | H14: 47 | I14: 72097 | J14: 71598 | K14: 167 | L14: #PepsiCoRefresh | M14: FestiveRadiance | N14: 5190 | O14: 0.071986352 | P14: DailyWellness | Q14: 45717 | R14: 45747 | S14: 180000
A15: P011 | B15: Instagram | C15: 45690 | D15: Story | E15: Check out our latest story on instagram! | F15: 1792 | G15: 614 | H15: 497 | I15: 25088 | J15: 24675 | K15: 65 | L15: #LiveForNow | M15: DailyWellness | N15: 2903 | O15: 0.11571269 | P15: No Campaign
A16: P012 | B16: Facebook | C16: 45494 | D16: Reel | E16: Check out our latest reel on facebook! | F16: 1946 | G16: 686 | H16: 377 | I16: 23352 | J16: 22982 | K16: 213 | L16: #LiveForNow | M16: NewYearRefresh | N16: 3009 | O16: 0.12885406 | P16: No Campaign
A17: P013 | B17: YouTube | C17: 45614 | D17: Carousel | E17: Check out our latest carousel on youtube! | F17: 1171 | G17: 286 | H17: 231 | I17: 22249 | J17: 21282 | K17: 114 | L17: #ThirstyForMore | M17: SummerSplash | N17: 1688 | O17: 0.075868578 | P17: No Campaign
A18: P014 | B18: Facebook | C18: 45704 | D18: Story | E18: Check out our latest story on facebook! | F18: 4242 | G18: 555 | H18: 131 | I18: 33936 | J18: 33802 | K18: 265 | L18: #LiveForNow | N18: 4928 | O18: 0.14521452 | P18: No Campaign
A19: P015 | B19: Facebook | C19: 45589 | D19: Video | E19: Check out our latest video on facebook! | F19: 3888 | G19: 604 | H19: 128 | I19: 77760 | J19: 77167 | K19: 20 | L19: #LiveForNow | M19: SummerSplash | N19: 4620 | O19: 0.05941358 | P19: FestiveRadiance | Q19: 45566 | R19: 45596 | S19: 200000
A20: P016 | B20: Facebook | C20: 45530 | D20: Text | E20: Check out our latest text on facebook! | F20: 3452 | G20: 377 | H20: 360 | I20: 55232 | J20: 55075 | K20: 87 | L20: #LiveForNow | M20: NewYearRefresh | N20: 4189 | O20: 0.075843714 | P20: No Campaign
A21: P017 | B21: Facebook | C21: 45782 | D21: Text | E21: Check out our latest text on facebook! | F21: 4441 | G21: 511 | H21: 70 | I21: 53292 | J21: 53082 | K21: 159 | L21: #ThirstyForMore | M21: DailyWellness | N21: 5022 | O21: 0.094235533 | P21: No Campaign
A22: P018 | B22: Instagram | C22: 45523 | D22: Reel | E22: Check out our latest reel on instagram! | F22: 3000 | G22: 382 | H22: 325 | I22: 36000 | J22: 35819 | K22: 19 | L22: #LiveForNow | M22: SummerSplash | N22: 3707 | O22: 0.10297222 | P22: No Campaign
A23: P019 | B23: Instagram | C23: 45466 | D23: Video | E23: Check out our latest video on instagram! | F23: 1071 | G23: 519 | H23: 22 | I23: 16065 | J23: 15865 | K23: 103 | L23: #PepsiCoRefresh | M23: DailyWellness | N23: 1612 | O23: 0.10034236 | P23: SummerSplash | Q23: 45458 | R23: 45488 | S23: 150000
A24: P020 | B24: Instagram | C24: 45544 | D24: Carousel | E24: Check out our latest carousel on instagram! | F24: 4054 | G24: 488 | H24: 373 | I24: 77026 | J24: 76881 | K24: 25 | L24: #PepsiCoRefresh | M24: SummerSplash | N24: 4915 | O24: 0.063809623 | P24: No Campaign
A25: P021 | B25: Instagram | C25: 45661 | D25: Reel | E25: Check out our latest reel on instagram! | F25: 4838 | G25: 640 | H25: 128 | I25: 72570 | J25: 72396 | K25: 83 | L25: #LiveForNow | M25: DailyWellness | N25: 5606 | O25: 0.077249552 | P25: NewYearRefresh | Q25: 45651 | R25: 45667 | S25: 250000
A26: P022 | B26: Facebook | C26: 45715 | D26: Text | E26: Check out our latest text on facebook! | F26: 1570 | G26: 187 | H26: 260 | I26: 25120 | J26: 24613 | K26: 133 | L26: #PepsiCoRefresh | M26: DailyWellness | N26: 2017 | O26: 0.080294586 | P26: No Campaign
A27: P023 | B27: Facebook | C27: 45602 | D27: Video | E27: Check out our latest video on facebook! | F27: 1606 | G27: 547 | H27: 316 | I27: 32120 | J27: 31736 | K27: 225 | L27: #PepsiCoRefresh | M27: FestiveRadiance | N27: 2469 | O27: 0.076867995 | P27: No Campaign
A28: P023 | B28: Facebook | C28: 45602 | D28: Video | E28: Check out our latest video on facebook! | F28: 1606 | G28: 547 | H28: 316 | I28: 32120 | J28: 31736 | K28: 225 | L28: #AnytimeIsPepsiTime | M28: FestiveRadiance | N28: 2469 | O28: 0.076867995 | P28: No Campaign
A29: P024 | B29: Facebook | C29: 45680 | D29: Video | E29: Check out our latest video on facebook! | F29: 3961 | G29: 761 | H29: 131 | I29: 67337 | J29: 66615 | K29: 161 | L29: #LiveForNow | M29: NewYearRefresh | N29: 4853 | O29: 0.072070333 | P29: No Campaign
A30: P025 | B30: Twitter | C30: 45757 | D30: Carousel | E30: Check out our latest carousel on twitter! | F30: 3128 | G30: 211 | H30: 197 | I30: 59432 | J30: 59182 | K30: 238 | L30: #ThirstyForMore | N30: 3536 | O30: 0.059496568 | P30: No Campaign
A31: P026 | B31: YouTube | C31: 45752 | D31: Reel | E31: Check out our latest reel on youtube! | F31: 3009 | G31: 413 | H31: 358 | I31: 42126 | J31: 41309 | K31: 211 | L31: #LiveForNow | M31: FestiveRadiance | N31: 3780 | O31: 0.089730808 | P31: No Campaign
A32: P027 | B32: YouTube | C32: 45552 | D32: Text | E32: Check out our latest text on youtube! | F32: 2076 | G32: 195 | H32: 104 | I32: 33216 | J32: 32244 | K32: 51 | L32: #LiveForNow | M32: DailyWellness | N32: 2375 | O32: 0.071501686 | P32: No Campaign
A33: P028 | B33: Instagram | C33: 45720 | D33: Video | E33: Check out our latest video on instagram! | F33: 432 | G33: 624 | H33: 123 | I33: 6912 | J33: 6259 | K33: 79 | L33: #LiveForNow | M33: DailyWellness | N33: 1179 | O33: 0.17057292 | P33: DailyWellness | Q33: 45717 | R33: 45747 | S33: 180000
A34: P029 | B34: Instagram | C34: 45688 | D34: Carousel | E34: Check out our latest carousel on instagram! | F34: 2566 | G34: 118 | H34: 37 | I34: 12830 | J34: 12264 | K34: 221 | L34: #LiveForNow | M34: NewYearRefresh | N34: 2721 | O34: 0.21208106 | P34: No Campaign
A35: P030 | B35: Instagram | C35: 45713 | D35: Video | E35: Check out our latest video on instagram! | F35: 3095 | G35: 39 | H35: 78 | I35: 55710 | J35: 54808 | K35: 93 | L35: #ThirstyForMore | N35: 3212 | O35: 0.057655717 | P35: No Campaign
A36: P031 | B36: Instagram | C36: 45642 | D36: Text | E36: Check out our latest text on instagram! | F36: 438 | G36: 153 | H36: 275 | I36: 3066 | J36: 2701 | K36: 282 | L36: #PepsiCoRefresh | M36: FestiveRadiance | N36: 866 | O36: 0.28245271 | P36: No Campaign
A37: P032 | B37: Twitter | C37: 45504 | D37: Carousel | E37: Check out our latest carousel on twitter! | F37: 2278 | G37: 10 | H37: 321 | I37: 13668 | J37: 12676 | K37: 275 | L37: #ThirstyForMore | M37: SummerSplash | N37: 2609 | O37: 0.19088382 | P37: No Campaign
A38: P033 | B38: Facebook | C38: 45525 | D38: Image | E38: Check out our latest image on facebook! | F38: 1407 | G38: 400 | H38: 351 | I38: 16884 | J38: 15954 | K38: 113 | L38: #PepsiCoRefresh | M38: SummerSplash | N38: 2158 | O38: 0.12781331 | P38: No Campaign
A39: P034 | B39: Facebook | C39: 45742 | D39: Text | E39: Check out our latest text on facebook! | F39: 1652 | G39: 89 | H39: 357 | I39: 29736 | J39: 28771 | K39: 215 | L39: #PepsiCoRefresh | M39: NewYearRefresh | N39: 2098 | O39: 0.07055421 | P39: DailyWellness | Q39: 45717 | R39: 45747 | S39: 180000
A40: P035 | B40: Instagram | C40: 45626 | D40: Video | E40: Check out our latest video on instagram! | F40: 3775 | G40: 16 | H40: 239 | I40: 33975 | J40: 33310 | K40: 271 | L40: #LiveForNow | M40: FestiveRadiance | N40: 4030 | O40: 0.11861663 | P40: No Campaign
...

Sheet Hashtag_Performanance
A3: Row Labels | B3: Average of Clicks | C3: Count of Hashtags Used
A4: #AnytimeIsPepsiTime | B4: 161.2 | C4: 15
A5: #BetterWithPepsi | B5: 114.85714 | C5: 7
A6: #LiveForNow | B6: 144.03883 | C6: 103
A7: #PepsiCoRefresh | B7: 158.65421 | C7: 107
A8: #SmoothLikeNitroPepsi | B8: 111.8 | C8: 5
A9: #ThirstyForMore | B9: 151.52941 | C9: 102
A10: Grand Total | B10: 150.58702 | C10: 339
